<?xml version="1.0" encoding="utf-8"?>
<!-- This URDF was automatically created by SolidWorks to URDF Exporter! Originally created by Stephen Brawner (brawner@gmail.com)
     Commit Version: 1.6.0-1-g15f4949  Build Version: 1.6.7594.29634
     For more information, please see http://wiki.ros.org/sw_urdf_exporter -->
<robot
  name="arm_simulation_urdf">
  <!--Fake link without inertial properties to appease KDL-->
  <link
    name = "virtual_link">
  </link>

  <link
    name="base_link">
    <inertial>
      <origin
        xyz="0.095192 0.08773 0.0015875"
        rpy="0 0 0" />
      <mass
        value="0.091414" />
      <inertia
        ixx="0.00024615"
        ixy="1.8237E-07"
        ixz="-3.3633E-22"
        iyy="0.00030854"
        iyz="-5.1548E-23"
        izz="0.00055454" />
    </inertial>
    <visual>
      <origin
        xyz="0 0 0"
        rpy="0 0 0" />
      <geometry>
        <mesh
          filename="package://arm_simulation_urdf/meshes/base_link.STL" />
      </geometry>
      <material
        name="">
        <color
          rgba="0.79216 0.81961 0.93333 1" />
      </material>
    </visual>
    <collision>
      <origin
        xyz="0 0 0"
        rpy="0 0 0" />
      <geometry>
        <mesh
          filename="package://arm_simulation_urdf/meshes/base_link.STL" />
      </geometry>
    </collision>
  </link>
  <!--virtual joint to take care of virtual link-->
  <joint
    name = "virtual_joint_1"
    type = "fixed">
    <parent link="virtual_link"/>
    <child link="base_link"/>
  </joint>    
  <link
    name="waist_link">
    <inertial>
      <origin
        xyz="-0.011164 -0.012835 0.024768"
        rpy="0 0 0" />
      <mass
        value="0.2767" />
      <inertia
        ixx="0.00025393"
        ixy="2.1958E-06"
        ixz="1.4348E-19"
        iyy="0.0002269"
        iyz="-4.2962E-18"
        izz="0.00043362" />
    </inertial>
    <visual>
      <origin
        xyz="0 0 0"
        rpy="0 0 0" />
      <geometry>
        <mesh
          filename="package://arm_simulation_urdf/meshes/waist_link.STL" />
      </geometry>
      <material
        name="">
        <color
          rgba="0.79216 0.81961 0.93333 1" />
      </material>
    </visual>
    <collision>
      <origin
        xyz="0 0 0"
        rpy="0 0 0" />
      <geometry>
        <mesh
          filename="package://arm_simulation_urdf/meshes/waist_link.STL" />
      </geometry>
    </collision>
  </link>
  <joint
    name="waist"
    type="revolute">
    <origin
      xyz="0.09525 0.06985 0.003175"
      rpy="0 0 0" />
    <parent
      link="base_link" />
    <child
      link="waist_link" />
    <axis
      xyz="0 0 1" />
    <limit
      lower="-3.14"
      upper="3.14"
      effort="10"
      velocity="10" />
  </joint>
  <link
    name="shoulder_link">
    <inertial>
      <origin
        xyz="0.19756 1.8568E-05 -0.012791"
        rpy="0 0 0" />
      <mass
        value="1.0561" />
      <inertia
        ixx="0.0026076"
        ixy="-2.904E-06"
        ixz="0.0022586"
        iyy="0.017622"
        iyz="3.9599E-10"
        izz="0.016951" />
    </inertial>
    <visual>
      <origin
        xyz="0 0 0"
        rpy="0 0 0" />
      <geometry>
        <mesh
          filename="package://arm_simulation_urdf/meshes/shoulder_link.STL" />
      </geometry>
      <material
        name="">
        <color
          rgba="0.89804 0.91765 0.92941 1" />
      </material>
    </visual>
    <collision>
      <origin
        xyz="0 0 0"
        rpy="0 0 0" />
      <geometry>
        <mesh
          filename="package://arm_simulation_urdf/meshes/shoulder_link.STL" />
      </geometry>
    </collision>
  </link>
  <joint
    name="shoulder"
    type="revolute">
    <origin
      xyz="-0.0037159 -0.0013538 0.072656"
      rpy="0 0 0" />
    <parent
      link="waist_link" />
    <child
      link="shoulder_link" />
    <axis
      xyz="0 1 0" />
    <limit
      lower="-3.14"
      upper="0.20"
      effort="10"
      velocity="10" />
  </joint>
  <link
    name="elbow_link">
    <inertial>
      <origin
        xyz="0.19985 5.2725E-09 0.0011935"
        rpy="0 0 0" />
      <mass
        value="0.80172" />
      <inertia
        ixx="0.00095125"
        ixy="-5.1408E-10"
        ixz="0.00021056"
        iyy="0.012015"
        iyz="-2.2103E-11"
        izz="0.012074" />
    </inertial>
    <visual>
      <origin
        xyz="0 0 0"
        rpy="0 0 0" />
      <geometry>
        <mesh
          filename="package://arm_simulation_urdf/meshes/elbow_link.STL" />
      </geometry>
      <material
        name="">
        <color
          rgba="0.89804 0.91765 0.92941 1" />
      </material>
    </visual>
    <collision>
      <origin
        xyz="0 0 0"
        rpy="0 0 0" />
      <geometry>
        <mesh
          filename="package://arm_simulation_urdf/meshes/elbow_link.STL" />
      </geometry>
    </collision>
  </link>
  <joint
    name="elbow"
    type="revolute">
    <origin
      xyz="0.38496 0 -0.096803"
      rpy="0 0.7854 0" />
    <parent
      link="shoulder_link" />
    <child
      link="elbow_link" />
    <axis
      xyz="0 1 0" />
    <limit
      lower="-1.17"
      upper="2.25"
      effort="10"
      velocity="10" />
  </joint>
  <link
    name="wrist_link">
    <inertial>
      <origin
        xyz="0.079682 1.2703E-06 -0.049588"
        rpy="0 0 0" />
      <mass
        value="0.16196" />
      <inertia
        ixx="0.00039422"
        ixy="7.0499E-09"
        ixz="2.5622E-05"
        iyy="0.00022921"
        iyz="-1.2793E-08"
        izz="0.00028411" />
    </inertial>
    <visual>
      <origin
        xyz="0 0 0"
        rpy="0 0 0" />
      <geometry>
        <mesh
          filename="package://arm_simulation_urdf/meshes/wrist_link.STL" />
      </geometry>
      <material
        name="">
        <color
          rgba="0.89804 0.91765 0.92941 1" />
      </material>
    </visual>
    <collision>
      <origin
        xyz="0 0 0"
        rpy="0 0 0" />
      <geometry>
        <mesh
          filename="package://arm_simulation_urdf/meshes/wrist_link.STL" />
      </geometry>
    </collision>
  </link>
  <joint
    name="wrist"
    type="revolute">
    <origin
      xyz="0.40555 0 0"
      rpy="0 0 0" />
    <parent
      link="elbow_link" />
    <child
      link="wrist_link" />
    <axis
      xyz="0 1 0" />
    <limit
      lower="-1.91"
      upper="1.87"
      effort="10"
      velocity="10" />
  </joint>
</robot>
